{
 "cells": [
  {
   "cell_type": "markdown",
   "metadata": {},
   "source": [
    "# Reproduce CheXNet: Explore Predictions"
   ]
  },
  {
   "cell_type": "markdown",
   "metadata": {},
   "source": [
    "## Import other modules and pandas"
   ]
  },
  {
   "cell_type": "code",
   "execution_count": 10,
   "metadata": {},
   "outputs": [],
   "source": [
    "import visualize_prediction as V\n",
    "import pandas as pd\n",
    "\n",
    "#suppress pytorch warnings about source code changes\n",
    "import warnings\n",
    "warnings.filterwarnings('ignore')"
   ]
  },
  {
   "cell_type": "markdown",
   "metadata": {},
   "source": [
    "## Settings for review\n",
    "We can examine individual results in more detail, seeing probabilities of disease for test images. \n",
    "\n",
    "We get you started with a small number of the images from the large NIH dataset. \n",
    "\n",
    "To explore the full dataset, [download images from NIH (large, ~40gb compressed)](https://nihcc.app.box.com/v/ChestXray-NIHCC), extract all tar.gz files to a single folder, place that path  below and set STARTER_IMAGES=False"
   ]
  },
  {
   "cell_type": "code",
   "execution_count": 11,
   "metadata": {},
   "outputs": [],
   "source": [
    "STARTER_IMAGES=False\n",
    "PATH_TO_IMAGES = \"dataset/\"\n",
    "\n",
    "#STARTER_IMAGES=False\n",
    "#PATH_TO_IMAGES = \"your path to NIH data here\""
   ]
  },
  {
   "cell_type": "markdown",
   "metadata": {},
   "source": [
    "Load pretrained model (part of cloned repo; should not need to change path unless you want to point to one you retrained)"
   ]
  },
  {
   "cell_type": "code",
   "execution_count": 12,
   "metadata": {},
   "outputs": [],
   "source": [
    "PATH_TO_MODEL = \"pretrained/checkpoint\""
   ]
  },
  {
   "cell_type": "markdown",
   "metadata": {},
   "source": [
    "Pick the finding you want to see positive examples of:\n",
    "\n",
    "LABEL can be set to any of:\n",
    "- Atelectasis\n",
    "- Cardiomegaly\n",
    "- Consolidation\n",
    "- Edema\n",
    "- Effusion\n",
    "- Emphysema\n",
    "- Fibrosis\n",
    "- Hernia\n",
    "- Infiltration\n",
    "- Mass\n",
    "- Nodule\n",
    "- Pleural_Thickening\n",
    "- Pneumonia\n",
    "- Pneumothorax\n"
   ]
  },
  {
   "cell_type": "code",
   "execution_count": 14,
   "metadata": {},
   "outputs": [],
   "source": [
    "LABEL=\"Pneumonia\""
   ]
  },
  {
   "cell_type": "markdown",
   "metadata": {},
   "source": [
    "It's more interesting when initially exploring to see cases positive for pathology of interest:"
   ]
  },
  {
   "cell_type": "code",
   "execution_count": 15,
   "metadata": {},
   "outputs": [],
   "source": [
    "POSITIVE_FINDINGS_ONLY=True"
   ]
  },
  {
   "cell_type": "markdown",
   "metadata": {},
   "source": [
    "## Load data\n",
    "\n",
    "This loads up dataloader and model (note: only test images not used for model training are loaded)."
   ]
  },
  {
   "cell_type": "code",
   "execution_count": 16,
   "metadata": {},
   "outputs": [
    {
     "name": "stdout",
     "output_type": "stream",
     "text": [
      "Cases for review:\n",
      "242\n"
     ]
    }
   ],
   "source": [
    "dataloader,model= V.load_data(PATH_TO_IMAGES,LABEL,PATH_TO_MODEL,POSITIVE_FINDINGS_ONLY,STARTER_IMAGES)\n",
    "print(\"Cases for review:\")\n",
    "print(len(dataloader))"
   ]
  },
  {
   "cell_type": "markdown",
   "metadata": {},
   "source": [
    "## Examine individual cases\n",
    "\n",
    "To explore, run code below to see a random case positive for your selected finding, a heatmap indicating the most influential regions of the image, and the model's estimated probabilities for findings. For many diagnoses, you can see that the model uses features outside the expected region to calibrate its predictions -- [you can read my discussion about this here](https://medium.com/@jrzech/what-are-radiological-deep-learning-models-actually-learning-f97a546c5b98).\n",
    "\n",
    "Please note that:\n",
    "1) the NIH dataset was noisily labeled by automatically extracting labels from text reports written by radiologists, as described in paper [here](https://arxiv.org/pdf/1705.02315.pdf) and analyzed [here](https://lukeoakdenrayner.wordpress.com/2017/12/18/the-chestxray14-dataset-problems/), so we should not be surprised to see inaccuracies in the provided ground truth labels \n",
    "2) high AUCs can be achieved even if many positive cases are assigned absolutely low probabilities of disease, as AUC depends on the relative ranking of probabilities between cases. \n",
    "\n",
    "You can run the below cell repeatedly to see different examples:"
   ]
  },
  {
   "cell_type": "code",
   "execution_count": 17,
   "metadata": {
    "scrolled": false
   },
   "outputs": [
    {
     "ename": "FileNotFoundError",
     "evalue": "Traceback (most recent call last):\n  File \"/home/azael/AzaEnv/lib/python3.5/site-packages/torch/utils/data/dataloader.py\", line 55, in _worker_loop\n    samples = collate_fn([dataset[i] for i in batch_indices])\n  File \"/home/azael/AzaEnv/lib/python3.5/site-packages/torch/utils/data/dataloader.py\", line 55, in <listcomp>\n    samples = collate_fn([dataset[i] for i in batch_indices])\n  File \"/home/azael/Trabalhos/MO444/Tf/reproduce-chexnet/cxr_dataset.py\", line 69, in __getitem__\n    self.df.index[idx]))\n  File \"/home/azael/AzaEnv/lib/python3.5/site-packages/PIL/Image.py\", line 2609, in open\n    fp = builtins.open(filename, \"rb\")\nFileNotFoundError: [Errno 2] No such file or directory: 'dataset/00000165_001.png'\n",
     "output_type": "error",
     "traceback": [
      "\u001b[0;31m---------------------------------------------------------------------------\u001b[0m",
      "\u001b[0;31mFileNotFoundError\u001b[0m                         Traceback (most recent call last)",
      "\u001b[0;32m<ipython-input-17-68b2fffbc12d>\u001b[0m in \u001b[0;36m<module>\u001b[0;34m()\u001b[0m\n\u001b[0;32m----> 1\u001b[0;31m \u001b[0mpreds\u001b[0m\u001b[0;34m=\u001b[0m\u001b[0mV\u001b[0m\u001b[0;34m.\u001b[0m\u001b[0mshow_next\u001b[0m\u001b[0;34m(\u001b[0m\u001b[0mdataloader\u001b[0m\u001b[0;34m,\u001b[0m\u001b[0mmodel\u001b[0m\u001b[0;34m,\u001b[0m \u001b[0mLABEL\u001b[0m\u001b[0;34m)\u001b[0m\u001b[0;34m\u001b[0m\u001b[0m\n\u001b[0m\u001b[1;32m      2\u001b[0m \u001b[0mpreds\u001b[0m\u001b[0;34m\u001b[0m\u001b[0m\n",
      "\u001b[0;32m~/Trabalhos/MO444/Tf/reproduce-chexnet/visualize_prediction.py\u001b[0m in \u001b[0;36mshow_next\u001b[0;34m(dataloader, model, LABEL)\u001b[0m\n\u001b[1;32m    250\u001b[0m     \u001b[0;31m# get next iter from dataloader\u001b[0m\u001b[0;34m\u001b[0m\u001b[0;34m\u001b[0m\u001b[0m\n\u001b[1;32m    251\u001b[0m     \u001b[0;32mtry\u001b[0m\u001b[0;34m:\u001b[0m\u001b[0;34m\u001b[0m\u001b[0m\n\u001b[0;32m--> 252\u001b[0;31m         \u001b[0minputs\u001b[0m\u001b[0;34m,\u001b[0m \u001b[0mlabels\u001b[0m\u001b[0;34m,\u001b[0m \u001b[0mfilename\u001b[0m \u001b[0;34m=\u001b[0m \u001b[0mnext\u001b[0m\u001b[0;34m(\u001b[0m\u001b[0mdataloader\u001b[0m\u001b[0;34m)\u001b[0m\u001b[0;34m\u001b[0m\u001b[0m\n\u001b[0m\u001b[1;32m    253\u001b[0m     \u001b[0;32mexcept\u001b[0m \u001b[0mStopIteration\u001b[0m\u001b[0;34m:\u001b[0m\u001b[0;34m\u001b[0m\u001b[0m\n\u001b[1;32m    254\u001b[0m         \u001b[0mprint\u001b[0m\u001b[0;34m(\u001b[0m\u001b[0;34m\"All examples exhausted - rerun cells above to generate new examples to review\"\u001b[0m\u001b[0;34m)\u001b[0m\u001b[0;34m\u001b[0m\u001b[0m\n",
      "\u001b[0;32m~/AzaEnv/lib/python3.5/site-packages/torch/utils/data/dataloader.py\u001b[0m in \u001b[0;36m__next__\u001b[0;34m(self)\u001b[0m\n\u001b[1;32m    279\u001b[0m                 \u001b[0mself\u001b[0m\u001b[0;34m.\u001b[0m\u001b[0mreorder_dict\u001b[0m\u001b[0;34m[\u001b[0m\u001b[0midx\u001b[0m\u001b[0;34m]\u001b[0m \u001b[0;34m=\u001b[0m \u001b[0mbatch\u001b[0m\u001b[0;34m\u001b[0m\u001b[0m\n\u001b[1;32m    280\u001b[0m                 \u001b[0;32mcontinue\u001b[0m\u001b[0;34m\u001b[0m\u001b[0m\n\u001b[0;32m--> 281\u001b[0;31m             \u001b[0;32mreturn\u001b[0m \u001b[0mself\u001b[0m\u001b[0;34m.\u001b[0m\u001b[0m_process_next_batch\u001b[0m\u001b[0;34m(\u001b[0m\u001b[0mbatch\u001b[0m\u001b[0;34m)\u001b[0m\u001b[0;34m\u001b[0m\u001b[0m\n\u001b[0m\u001b[1;32m    282\u001b[0m \u001b[0;34m\u001b[0m\u001b[0m\n\u001b[1;32m    283\u001b[0m     \u001b[0mnext\u001b[0m \u001b[0;34m=\u001b[0m \u001b[0m__next__\u001b[0m  \u001b[0;31m# Python 2 compatibility\u001b[0m\u001b[0;34m\u001b[0m\u001b[0m\n",
      "\u001b[0;32m~/AzaEnv/lib/python3.5/site-packages/torch/utils/data/dataloader.py\u001b[0m in \u001b[0;36m_process_next_batch\u001b[0;34m(self, batch)\u001b[0m\n\u001b[1;32m    299\u001b[0m         \u001b[0mself\u001b[0m\u001b[0;34m.\u001b[0m\u001b[0m_put_indices\u001b[0m\u001b[0;34m(\u001b[0m\u001b[0;34m)\u001b[0m\u001b[0;34m\u001b[0m\u001b[0m\n\u001b[1;32m    300\u001b[0m         \u001b[0;32mif\u001b[0m \u001b[0misinstance\u001b[0m\u001b[0;34m(\u001b[0m\u001b[0mbatch\u001b[0m\u001b[0;34m,\u001b[0m \u001b[0mExceptionWrapper\u001b[0m\u001b[0;34m)\u001b[0m\u001b[0;34m:\u001b[0m\u001b[0;34m\u001b[0m\u001b[0m\n\u001b[0;32m--> 301\u001b[0;31m             \u001b[0;32mraise\u001b[0m \u001b[0mbatch\u001b[0m\u001b[0;34m.\u001b[0m\u001b[0mexc_type\u001b[0m\u001b[0;34m(\u001b[0m\u001b[0mbatch\u001b[0m\u001b[0;34m.\u001b[0m\u001b[0mexc_msg\u001b[0m\u001b[0;34m)\u001b[0m\u001b[0;34m\u001b[0m\u001b[0m\n\u001b[0m\u001b[1;32m    302\u001b[0m         \u001b[0;32mreturn\u001b[0m \u001b[0mbatch\u001b[0m\u001b[0;34m\u001b[0m\u001b[0m\n\u001b[1;32m    303\u001b[0m \u001b[0;34m\u001b[0m\u001b[0m\n",
      "\u001b[0;31mFileNotFoundError\u001b[0m: Traceback (most recent call last):\n  File \"/home/azael/AzaEnv/lib/python3.5/site-packages/torch/utils/data/dataloader.py\", line 55, in _worker_loop\n    samples = collate_fn([dataset[i] for i in batch_indices])\n  File \"/home/azael/AzaEnv/lib/python3.5/site-packages/torch/utils/data/dataloader.py\", line 55, in <listcomp>\n    samples = collate_fn([dataset[i] for i in batch_indices])\n  File \"/home/azael/Trabalhos/MO444/Tf/reproduce-chexnet/cxr_dataset.py\", line 69, in __getitem__\n    self.df.index[idx]))\n  File \"/home/azael/AzaEnv/lib/python3.5/site-packages/PIL/Image.py\", line 2609, in open\n    fp = builtins.open(filename, \"rb\")\nFileNotFoundError: [Errno 2] No such file or directory: 'dataset/00000165_001.png'\n"
     ]
    }
   ],
   "source": [
    "preds=V.show_next(dataloader,model, LABEL)\n",
    "preds"
   ]
  },
  {
   "cell_type": "code",
   "execution_count": null,
   "metadata": {},
   "outputs": [],
   "source": []
  }
 ],
 "metadata": {
  "anaconda-cloud": {},
  "kernelspec": {
   "display_name": "py35env",
   "language": "python",
   "name": "py35env"
  },
  "language_info": {
   "codemirror_mode": {
    "name": "ipython",
    "version": 3
   },
   "file_extension": ".py",
   "mimetype": "text/x-python",
   "name": "python",
   "nbconvert_exporter": "python",
   "pygments_lexer": "ipython3",
   "version": "3.5.2"
  }
 },
 "nbformat": 4,
 "nbformat_minor": 2
}
